Workbook

Sheet Journal de travail
F1: Journal de travail
A2: Auteur: | C2: Scherrer Eliott | F2: Projet: | G2: P_FUN 323 - PlotThoseLines
A3: Temps total: | C3: =QUOTIENT(E4,60)&" heures "&MOD(E4,60)&" minutes" -> 27 heures 20 minutes | F3: Date: | G3: 25 août 2025 au 31 octobre 2025
C4: =SUBTOTAL(9,$C$7:$C$531)*60 -> 780 | D4: =SUBTOTAL(9,$D$7:$D$531) -> 860 | E4: =SUM(C4:D4) -> 1640
C5: Temps
A6: Semaine | B6: Jour | C6: h. | D6: min. | E6: Type | F6: Description | G6: Remarques/problèmes
A7: =IF(ISBLANK(B7),"",_xlfn.ISOWEEKNUM('Journal de travail'!$B7)) -> 35 | B7: 45896 | D7: 45 | E7: Analyse | F7: Recherches sur les différents marchés/données à analyser avec PTL | G7: J'ai fini par choisir le marché des crypto-monnaies
A8: =IF(ISBLANK(B8),"",_xlfn.ISOWEEKNUM('Journal de travail'!$B8)) -> 35 | B8: 45896 | C8: 2 | D8: 15 | E8: Analyse | F8: Ecriture des User Stories | G8: Sur Jira | M8: Analyse | N8: 1 | O8: 0
A9: =IF(ISBLANK(B9),"",_xlfn.ISOWEEKNUM('Journal de travail'!$B9)) -> 36 | B9: 45903 | D9: 45 | E9: Analyse | F9: Début de planification | G9: Sur Jira | M9: Implémentation | N9: 2 | O9: 5
A10: =IF(ISBLANK(B10),"",_xlfn.ISOWEEKNUM('Journal de travail'!$B10)) -> 36 | B10: 45903 | D10: 10 | E10: Analyse | F10: Création du repo GitHub et du GitHub Projects | G10: Car l'essai gratuit de Jira ne durait que 2 semaines | M10: Test | N10: 3 | O10: 10
A11: =IF(ISBLANK(B11),"",_xlfn.ISOWEEKNUM('Journal de travail'!$B11)) -> 36 | B11: 45903 | C11: 1 | E11: Analyse | F11: Changement de plateforme vers GitHub Projects pour les US et la planification | G11: Car l'essai gratuit de Jira ne durait que 2 semaines | M11: Documentation | N11: 4 | O11: 15
A12: =IF(ISBLANK(B12),"",_xlfn.ISOWEEKNUM('Journal de travail'!$B12)) -> 36 | B12: 45903 | D12: 20 | E12: Analyse | F12: Ecriture d'une template pour les Users Stories | M12: Absent | N12: 5 | O12: 20
A13: =IF(ISBLANK(B13),"",_xlfn.ISOWEEKNUM('Journal de travail'!$B13)) -> 36 | B13: 45903 | D13: 30 | E13: Analyse | F13: Affinage de certaines US | N13: 6 | O13: 25
A14: =IF(ISBLANK(B14),"",_xlfn.ISOWEEKNUM('Journal de travail'!$B14)) -> 37 | B14: 45910 | C14: 2 | D14: 30 | E14: Analyse | F14: Création du mockup des pages Charts, Assets et Settings avec les visuels des intéractions | N14: 7 | O14: 30
A15: =IF(ISBLANK(B15),"",_xlfn.ISOWEEKNUM('Journal de travail'!$B15)) -> 37 | B15: 45910 | D15: 15 | E15: Analyse | F15: Recherches et analyses sur différents frameworks C# pour créer des applications | G15: J'ai fini par choisir Blazor & MAUI Hybride | N15: 8 | O15: 35
A16: =IF(ISBLANK(B16),"",_xlfn.ISOWEEKNUM('Journal de travail'!$B16)) -> 37 | B16: 45910 | D16: 15 | E16: Analyse | F16: Recherches sur le fonctionement/structure de Blazor MAUI Hybride | O16: 40
A17: =IF(ISBLANK(B17),"",_xlfn.ISOWEEKNUM('Journal de travail'!$B17)) -> 38 | B17: 45917 | D17: 10 | E17: Implémentation | F17: Création de la solution Blazor MAUI Hybride | O17: 45
A18: =IF(ISBLANK(B18),"",_xlfn.ISOWEEKNUM('Journal de travail'!$B18)) -> 38 | B18: 45917 | D18: 30 | E18: Analyse | F18: Recherche sur les différentes APIs proposant des données historiques de crypto-monnaies | G18: J'ai fini par choisir TokenInsight | O18: 50
A19: =IF(ISBLANK(B19),"",_xlfn.ISOWEEKNUM('Journal de travail'!$B19)) -> 38 | B19: 45917 | D19: 50 | E19: Analyse | F19: Recréation de la sidebar Blazor pour qu'elle corresponde aux maquettes | O19: 55
A20: =IF(ISBLANK(B20),"",_xlfn.ISOWEEKNUM('Journal de travail'!$B20)) -> 38 | B20: 45917 | D20: 30 | E20: Implémentation | F20: Création d'un app très simple pour récupérer des données depuis l'API de TokenInsight | G20: Ne figure pas sur le repo car c'était simplement pour se familiariser avec l'utilisation des Blazor et de l'API TokenInsight
A21: =IF(ISBLANK(B21),"",_xlfn.ISOWEEKNUM('Journal de travail'!$B21)) -> 38 | B21: 45917 | D21: 30 | E21: Implémentation | F21: Implémentation de la recherche d'assets dans le projet principal
A22: =IF(ISBLANK(B22),"",_xlfn.ISOWEEKNUM('Journal de travail'!$B22)) -> 38 | B22: 45917 | D22: 30 | E22: Implémentation | F22: Début d'implémentation de la recherche de données historiques d'un asset
A23: =IF(ISBLANK(B23),"",_xlfn.ISOWEEKNUM('Journal de travail'!$B23)) -> 39 | B23: 45924 | D23: 10 | E23: Implémentation | F23: Fin de l'implémentation de la recherche de données historiques d'un asset
A24: =IF(ISBLANK(B24),"",_xlfn.ISOWEEKNUM('Journal de travail'!$B24)) -> 39 | B24: 45924 | D24: 40 | E24: Implémentation | F24: Implémentation de la sauvegarde des assets localement
A25: =IF(ISBLANK(B25),"",_xlfn.ISOWEEKNUM('Journal de travail'!$B25)) -> 39 | B25: 45924 | C25: 1 | E25: Implémentation | F25: Création d'un modal pour importer des assets depuis l'API
A26: =IF(ISBLANK(B26),"",_xlfn.ISOWEEKNUM('Journal de travail'!$B26)) -> 39 | B26: 45924 | D26: 20 | E26: Analyse | F26: Recherche de librairies pour afficher des graphiques en Blazor MAUI Hybride | G26: J'ai fini par choisir ApexCharts
A27: =IF(ISBLANK(B27),"",_xlfn.ISOWEEKNUM('Journal de travail'!$B27)) -> 39 | B27: 45924 | C27: 1 | E27: Implémentation | F27: Ajout du graphique qui affiche le prix et le volume de crpto-monnaire sur le temps
A28: =IF(ISBLANK(B28),"",_xlfn.ISOWEEKNUM('Journal de travail'!$B28)) -> 40 | B28: 45931 | D28: 30 | E28: Implémentation | F28: Implémentation de la page Settings pour gérer sa clé API
A29: =IF(ISBLANK(B29),"",_xlfn.ISOWEEKNUM('Journal de travail'!$B29)) -> 40 | B29: 45931 | C29: 1 | E29: Implémentation | F29: Transformer le graphique à ligne en graphique avec bougies | G29: En utilisant des données fictives pour les High, Low, Open, Close parce que notre API ne les fourni pas
A30: =IF(ISBLANK(B30),"",_xlfn.ISOWEEKNUM('Journal de travail'!$B30)) -> 40 | B30: 45931 | D30: 45 | E30: Implémentation | F30: Ajouter la selection d'interval comme dans la maquette
A31: =IF(ISBLANK(B31),"",_xlfn.ISOWEEKNUM('Journal de travail'!$B31)) -> 40 | B31: 45931 | D31: 15 | E31: Implémentation | F31: Charger les données API sans devoir cliquer sur le bouton "Fetch"
A32: =IF(ISBLANK(B32),"",_xlfn.ISOWEEKNUM('Journal de travail'!$B32)) -> 41 | B32: 45938 | D32: 10 | E32: Implémentation | F32: Inverser les couleurs du graph bougie | G32: Car c'était vert quand le prix descendait et rouge quand il montait au lieu du contraire
A33: =IF(ISBLANK(B33),"",_xlfn.ISOWEEKNUM('Journal de travail'!$B33)) -> 41 | B33: 45938 | C33: 1 | D33: 20 | E33: Implémentation | F33: Ajout des multi séries temporelles
A34: =IF(ISBLANK(B34),"",_xlfn.ISOWEEKNUM('Journal de travail'!$B34)) -> 41 | B34: 45938 | D34: 30 | E34: Implémentation | F34: Faire en sorte que les pages ne se réinitialisent pas quand on revient dessus pour l'UX
A35: =IF(ISBLANK(B35),"",_xlfn.ISOWEEKNUM('Journal de travail'!$B35)) -> 41 | B35: 45938 | C35: 1 | E35: Implémentation | F35: Importer des fichiers de données localement | G35: Pas encore fini car j'ai encore des bugs
A36: =IF(ISBLANK(B36),"",_xlfn.ISOWEEKNUM('Journal de travail'!$B36)) -> 44 | B36: 45959 | D36: 10 | E36: Implémentation | F36: Cacher les scrollbars pour améliorer la clarté
A37: =IF(ISBLANK(B37),"",_xlfn.ISOWEEKNUM('Journal de travail'!$B37)) -> 44 | B37: 45959 | D37: 20 | E37: Implémentation | F37: Ajouter un formatage personalisé | G37: Afin de corriger un bug qui affichait beaucoup trop de zéros après la virgule sur l'axe Y de mes graphiques
A38: =IF(ISBLANK(B38),"",_xlfn.ISOWEEKNUM('Journal de travail'!$B38)) -> 44 | B38: 45959 | C38: 1 | E38: Implémentation | F38: Corriger un bug sur l'affichage de données locales pendant le parsage JSON
A39: =IF(ISBLANK(B39),"",_xlfn.ISOWEEKNUM('Journal de travail'!$B39)) -> 44 | B39: 45959 | D39: 20 | E39: Implémentation | F39: Désactiver les intervalles trop petit qand il y a pas assez de data points
A40: =IF(ISBLANK(B40),"",_xlfn.ISOWEEKNUM('Journal de travail'!$B40)) -> 44 | B40: 45959 | D40: 25 | E40: Implémentation | F40: Récolter les données des cryptos automatiquement au lieu d'utiliser un bouton
...

Sheet Plannification
E2: Total heures TPI | F2: 90 | G2: heures
E4: Plannification Effective | L4: Plannification Initiale
A5: Heures | B5: Minutes | C5: Total | E5: Type d'activité | F5: Total heures | G5: en % | L5: Type d'activité | M5: Total heures | N5: en %
A6: =SUMIF('Journal de travail'!$E$7:$E$532,Plannification!E6,'Journal de travail'!$C$7:$C$532)*60 -> 300 | B6: =SUMIF('Journal de travail'!$E$7:$E$532,Plannification!E6,'Journal de travail'!$D$7:$D$532) -> 325 | C6: =SUM(A6:B6) -> 625 | E6: ='Journal de travail'!M8 -> Analyse | F6: =QUOTIENT(SUM(A6:B6),60)&" h "&TEXT(MOD(SUM(A6:B6),60), "00")&" min" -> 10 h 25 min | G6: =SUM(A6:B6)/$C$11 -> 0.38109756 | L6: ='Journal de travail'!M8 -> Analyse | M6: =INT($F$2*N6)&" h "&TEXT(ROUND(MOD($F$2*N6,1)*60,0),"00")&" m" -> 18 h 00 m | N6: 0.2
A7: =SUMIF('Journal de travail'!$E$7:$E$532,Plannification!E7,'Journal de travail'!$C$7:$C$532)*60 -> 360 | B7: =SUMIF('Journal de travail'!$E$7:$E$532,Plannification!E7,'Journal de travail'!$D$7:$D$532) -> 445 | C7: =SUM(A7:B7) -> 805 | E7: ='Journal de travail'!M9 -> Implémentation | F7: =QUOTIENT(SUM(A7:B7),60)&" h "&TEXT(MOD(SUM(A7:B7),60), "00")&" min" -> 13 h 25 min | G7: =SUM(A7:B7)/$C$11 -> 0.49085366 | L7: ='Journal de travail'!M9 -> Implémentation | M7: =INT($F$2*N7)&" h "&TEXT(ROUND(MOD($F$2*N7,1)*60,0),"00")&" m" -> 31 h 30 m | N7: 0.35
A8: =SUMIF('Journal de travail'!$E$7:$E$532,Plannification!E8,'Journal de travail'!$C$7:$C$532)*60 -> 60 | B8: =SUMIF('Journal de travail'!$E$7:$E$532,Plannification!E8,'Journal de travail'!$D$7:$D$532) -> 30 | C8: =SUM(A8:B8) -> 90 | E8: ='Journal de travail'!M10 -> Test | F8: =QUOTIENT(SUM(A8:B8),60)&" h "&TEXT(MOD(SUM(A8:B8),60), "00")&" min" -> 1 h 30 min | G8: =SUM(A8:B8)/$C$11 -> 0.054878049 | L8: ='Journal de travail'!M10 -> Test | M8: =INT($F$2*N8)&" h "&TEXT(ROUND(MOD($F$2*N8,1)*60,0),"00")&" m" -> 4 h 30 m | N8: 0.05
A9: =SUMIF('Journal de travail'!$E$7:$E$532,Plannification!E9,'Journal de travail'!$C$7:$C$532)*60 -> 60 | B9: =SUMIF('Journal de travail'!$E$7:$E$532,Plannification!E9,'Journal de travail'!$D$7:$D$532) -> 60 | C9: =SUM(A9:B9) -> 120 | E9: ='Journal de travail'!M11 -> Documentation | F9: =QUOTIENT(SUM(A9:B9),60)&" h "&TEXT(MOD(SUM(A9:B9),60), "00")&" min" -> 2 h 00 min | G9: =SUM(A9:B9)/$C$11 -> 0.073170732 | L9: ='Journal de travail'!M11 -> Documentation | M9: =INT($F$2*N9)&" h "&TEXT(ROUND(MOD($F$2*N9,1)*60,0),"00")&" m" -> 36 h 00 m | N9: 0.4
A10: =SUMIF('Journal de travail'!$E$7:$E$532,Plannification!E10,'Journal de travail'!$C$7:$C$532)*60 -> 0 | B10: =SUMIF('Journal de travail'!$E$7:$E$532,Plannification!E10,'Journal de travail'!$D$7:$D$532) -> 0 | C10: =SUM(A10:B10) -> 0 | E10: Absent | F10: =QUOTIENT(SUM(A10:B10),60)&" h "&TEXT(MOD(SUM(A10:B10),60), "00")&" min" -> 0 h 00 min | G10: =SUM(A10:B10)/$C$11 -> 0 | L10: Absent | M10: =INT($F$2*N10)&" h "&TEXT(ROUND(MOD($F$2*N10,1)*60,0),"00")&" m" -> 0 h 00 m | N10: 0
A11: =SUM(A6:A10) -> 780 | B11: =SUM(B6:B10) -> 860 | C11: =SUM(A11:B11) -> 1640 | E11: Total | F11: =QUOTIENT(SUM(A11:B11),60)&" h "&TEXT(MOD(SUM(A11:B11),60), "00")&" min" -> 27 h 20 min | G11: =C11/C12 -> 0.3037037 | L11: Total | N11: =SUM(N6:N10) -> 1
C12: =F2*60 -> 5400

Sheet Initiale VS Effective
